<?xml version="1.0" encoding="utf-8"?>
<!-- =================================================================================== -->
<!-- |    This document was autogenerated by xacro from xarm_description/urdf/xarm7_with_gripper.xacro | -->
<!-- |    EDITING THIS FILE BY HAND IS NOT RECOMMENDED                                 | -->
<!-- =================================================================================== -->
<robot name="xarm7">
  <!--
  Author: Jimy Zhang <jimy.zhang@ufactory.cc> <jimy92@163.com>
  Contributers:
-->
  <gazebo>
    <plugin filename="libgazebo_ros_control.so" name="gazebo_ros_control">
      <robotNamespace>/xarm</robotNamespace>
      <!-- <controlPeriod>0.0001</controlPeriod> -->
      <robotSimType>gazebo_ros_control/DefaultRobotHWSim</robotSimType>
      <legacyModeNS>true</legacyModeNS>
      <!-- <preserveWorldVelocity>true</preserveWorldVelocity> -->
    </plugin>
  </gazebo>
  <link name="world"/>
  <joint name="world_joint" type="fixed">
    <parent link="world"/>
    <child link="link_base"/>
    <origin rpy="0 0 0" xyz="0 0 0"/>
  </joint>
  <material name="Black">
    <color rgba="0.0 0.0 0.0 1.0"/>
  </material>
  <material name="Red">
    <color rgba="0.8 0.0 0.0 1.0"/>
  </material>
  <material name="White">
    <color rgba="1.0 1.0 1.0 1.0"/>
  </material>
  <material name="Silver">
    <color rgba="0.753 0.753 0.753 1.0"/>
  </material>
  <link name="link_base">
    <inertial>
      <origin rpy="0 0 0" xyz="-0.021131 -0.0016302 0.056488"/>
      <mass value="2.612"/>
      <inertia ixx="0.0030595" ixy="0.00012259" ixz="-0.00062705" iyy="0.0037783" iyz="0.00027023" izz="0.0020125"/>
    </inertial>
    <visual>
      <origin rpy="0 0 0" xyz="0 0 0"/>
      <geometry>
        <mesh filename="package://xarm_description/meshes/xarm7/visual/link_base.STL"/>
      </geometry>
      <material name="White"/>
    </visual>
    <collision>
      <origin rpy="0 0 0" xyz="0 0 0"/>
      <geometry>
        <mesh filename="package://xarm_description/meshes/xarm7/visual/link_base.STL"/>
      </geometry>
    </collision>
  </link>
  <link name="link1">
    <inertial>
      <origin rpy="0 0 0" xyz="0.00013 0.0301 -0.012"/>
      <mass value="2.459"/>
      <inertia ixx="0.005795" ixy="-1.078E-05" ixz="-2.63E-05" iyy="0.004969" iyz="0.000911" izz="0.003428"/>
    </inertial>
    <visual>
      <origin rpy="0 0 0" xyz="0 0 0"/>
      <geometry>
        <mesh filename="package://xarm_description/meshes/xarm7/visual/link1.STL"/>
      </geometry>
      <material name="White"/>
    </visual>
    <collision>
      <origin rpy="0 0 0" xyz="0 0 0"/>
      <geometry>
        <mesh filename="package://xarm_description/meshes/xarm7/visual/link1.STL"/>
      </geometry>
    </collision>
  </link>
  <joint name="joint1" type="revolute">
    <origin rpy="0 0 0" xyz="0 0 0.267"/>
    <parent link="link_base"/>
    <child link="link1"/>
    <axis xyz="0 0 1"/>
    <limit effort="50" lower="-6.28318530718" upper="6.28318530718" velocity="3.14"/>
    <dynamics damping="10" friction="1"/>
  </joint>
  <link name="link2">
    <inertial>
      <origin rpy="0 0 0" xyz="0.0002 -0.12964 0.01692"/>
      <mass value="1.916"/>
      <inertia ixx="0.0097184" ixy="1.0E-06" ixz="-4.83E-06" iyy="0.0038705" iyz="0.0032" izz="0.007672"/>
    </inertial>
    <visual>
      <origin rpy="0 0 0" xyz="0 0 0"/>
      <geometry>
        <mesh filename="package://xarm_description/meshes/xarm7/visual/link2.STL"/>
      </geometry>
      <material name="White"/>
    </visual>
    <collision>
      <origin rpy="0 0 0" xyz="0 0 0"/>
      <geometry>
        <mesh filename="package://xarm_description/meshes/xarm7/visual/link2.STL"/>
      </geometry>
    </collision>
  </link>
  <joint name="joint2" type="revolute">
    <origin rpy="-1.5708 0 0" xyz="0 0 0"/>
    <parent link="link1"/>
    <child link="link2"/>
    <axis xyz="0 0 1"/>
    <limit effort="50" lower="-2.059" upper="2.0944" velocity="3.14"/>
    <dynamics damping="10" friction="1"/>
  </joint>
  <link name="link3">
    <inertial>
      <origin rpy="0 0 0" xyz="0.04676 -0.02526 -0.00746"/>
      <mass value="1.6854"/>
      <inertia ixx="0.0031588" ixy="-3.1443E-04" ixz="5.8658E-04" iyy="0.002682" iyz="-3.469E-04" izz="0.0027105"/>
    </inertial>
    <visual>
      <origin rpy="0 0 0" xyz="0 0 0"/>
      <geometry>
        <mesh filename="package://xarm_description/meshes/xarm7/visual/link3.STL"/>
      </geometry>
      <material name="White"/>
    </visual>
    <collision>
      <origin rpy="0 0 0" xyz="0 0 0"/>
      <geometry>
        <mesh filename="package://xarm_description/meshes/xarm7/visual/link3.STL"/>
      </geometry>
    </collision>
  </link>
  <joint name="joint3" type="revolute">
    <origin rpy="1.5708 0 0" xyz="0 -0.293 0"/>
    <parent link="link2"/>
    <child link="link3"/>
    <axis xyz="0 0 1"/>
    <limit effort="30" lower="-6.28318530718" upper="6.28318530718" velocity="3.14"/>
    <dynamics damping="5" friction="1"/>
  </joint>
  <link name="link4">
    <inertial>
      <origin rpy="0 0 0" xyz="0.07066 -0.11664 0.0117"/>
      <mass value="1.774"/>
      <inertia ixx="0.005967" ixy="-0.001382" ixz="-0.00088544" iyy="0.00363897" iyz="0.0017806" izz="0.005509226"/>
    </inertial>
    <visual>
      <origin rpy="0 0 0" xyz="0 0 0"/>
      <geometry>
        <mesh filename="package://xarm_description/meshes/xarm7/visual/link4.STL"/>
      </geometry>
      <material name="White"/>
    </visual>
    <collision>
      <origin rpy="0 0 0" xyz="0 0 0"/>
      <geometry>
        <mesh filename="package://xarm_description/meshes/xarm7/visual/link4.STL"/>
      </geometry>
    </collision>
  </link>
  <joint name="joint4" type="revolute">
    <origin rpy="1.5708 0 0" xyz="0.0525 0 0"/>
    <parent link="link3"/>
    <child link="link4"/>
    <axis xyz="0 0 1"/>
    <limit effort="30" lower="-0.19198" upper="3.927" velocity="3.14"/>
    <dynamics damping="5" friction="1"/>
  </joint>
  <link name="link5">
    <inertial>
      <origin rpy="0 0 0" xyz="-0.00031 0.01558 -0.0253"/>
      <mass value="1.357"/>
      <inertia ixx="0.005396" ixy="-1.53E-05" ixz="-6.7E-07" iyy="0.005" iyz="0.00020544" izz="0.00138734"/>
    </inertial>
    <visual>
      <origin rpy="0 0 0" xyz="0 0 0"/>
      <geometry>
        <mesh filename="package://xarm_description/meshes/xarm7/visual/link5.STL"/>
      </geometry>
      <material name="White"/>
    </visual>
    <collision>
      <origin rpy="0 0 0" xyz="0 0 0"/>
      <geometry>
        <mesh filename="package://xarm_description/meshes/xarm7/visual/link5.STL"/>
      </geometry>
    </collision>
  </link>
  <joint name="joint5" type="revolute">
    <origin rpy="1.5708 0 0" xyz="0.0775 -0.3425 0"/>
    <parent link="link4"/>
    <child link="link5"/>
    <axis xyz="0 0 1"/>
    <limit effort="30" lower="-6.28318530718" upper="6.28318530718" velocity="3.14"/>
    <dynamics damping="5" friction="1"/>
  </joint>
  <link name="link6">
    <inertial>
      <origin rpy="0 0 0" xyz="0.065 0.03336 0.02131"/>
      <mass value="1.362"/>
      <inertia ixx="0.0015057" ixy="0.000496735" ixz="-2.9968E-04" iyy="0.0019297" iyz="-1.5E-04" izz="0.0024"/>
    </inertial>
    <visual>
      <origin rpy="0 0 0" xyz="0 0 0"/>
      <geometry>
        <mesh filename="package://xarm_description/meshes/xarm7/visual/link6.STL"/>
      </geometry>
      <material name="White"/>
    </visual>
    <collision>
      <origin rpy="0 0 0" xyz="0 0 0"/>
      <geometry>
        <mesh filename="package://xarm_description/meshes/xarm7/visual/link6.STL"/>
      </geometry>
    </collision>
  </link>
  <joint name="joint6" type="revolute">
    <origin rpy="1.5708 0 0" xyz="0 0 0"/>
    <parent link="link5"/>
    <child link="link6"/>
    <axis xyz="0 0 1"/>
    <limit effort="20" lower="-1.69297" upper="3.14159265359" velocity="3.14"/>
    <dynamics damping="2" friction="1"/>
  </joint>
  <link name="link7">
    <inertial>
      <origin rpy="0 0 0" xyz="0 -0.00677 -0.01098"/>
      <mass value="0.17"/>
      <inertia ixx="9.3E-05" ixy="0.0" ixz="0.0" iyy="5.87E-05" iyz="3.6E-06" izz="1.32E-04"/>
    </inertial>
    <visual>
      <origin rpy="0 0 0" xyz="0 0 0"/>
      <geometry>
        <mesh filename="package://xarm_description/meshes/xarm7/visual/link7.STL"/>
      </geometry>
      <material name="Silver"/>
    </visual>
    <collision>
      <origin rpy="0 0 0" xyz="0 0 0"/>
      <geometry>
        <mesh filename="package://xarm_description/meshes/collision/end_tool.STL"/>
      </geometry>
    </collision>
  </link>
  <joint name="joint7" type="revolute">
    <origin rpy="-1.5708 0 0" xyz="0.076 0.097 0"/>
    <parent link="link6"/>
    <child link="link7"/>
    <axis xyz="0 0 1"/>
    <limit effort="20" lower="-6.28318530718" upper="6.28318530718" velocity="3.14"/>
    <dynamics damping="2" friction="1"/>
  </joint>
  <link name="link_eef"/>
  <joint name="joint_eef" type="fixed">
    <origin rpy="0 0 0" xyz="0 0 0"/>
    <parent link="link7"/>
    <child link="link_eef"/>
  </joint>
  <transmission name="tran1">
    <type>transmission_interface/SimpleTransmission</type>
    <joint name="joint1">
      <hardwareInterface>hardware_interface/PositionJointInterface</hardwareInterface>
    </joint>
    <actuator name="motor1">
      <hardwareInterface>hardware_interface/PositionJointInterface</hardwareInterface>
      <mechanicalReduction>100</mechanicalReduction>
    </actuator>
  </transmission>
  <transmission name="tran2">
    <type>transmission_interface/SimpleTransmission</type>
    <joint name="joint2">
      <hardwareInterface>hardware_interface/PositionJointInterface</hardwareInterface>
    </joint>
    <actuator name="motor2">
      <hardwareInterface>hardware_interface/PositionJointInterface</hardwareInterface>
      <mechanicalReduction>100</mechanicalReduction>
    </actuator>
  </transmission>
  <transmission name="tran3">
    <type>transmission_interface/SimpleTransmission</type>
    <joint name="joint3">
      <hardwareInterface>hardware_interface/PositionJointInterface</hardwareInterface>
    </joint>
    <actuator name="motor3">
      <hardwareInterface>hardware_interface/PositionJointInterface</hardwareInterface>
      <mechanicalReduction>100</mechanicalReduction>
    </actuator>
  </transmission>
  <transmission name="tran4">
    <type>transmission_interface/SimpleTransmission</type>
    <joint name="joint4">
      <hardwareInterface>hardware_interface/PositionJointInterface</hardwareInterface>
    </joint>
    <actuator name="motor3">
      <hardwareInterface>hardware_interface/PositionJointInterface</hardwareInterface>
      <mechanicalReduction>100</mechanicalReduction>
    </actuator>
  </transmission>
  <transmission name="tran5">
    <type>transmission_interface/SimpleTransmission</type>
    <joint name="joint5">
      <hardwareInterface>hardware_interface/PositionJointInterface</hardwareInterface>
    </joint>
    <actuator name="motor5">
      <hardwareInterface>hardware_interface/PositionJointInterface</hardwareInterface>
      <mechanicalReduction>100</mechanicalReduction>
    </actuator>
  </transmission>
  <transmission name="tran6">
    <type>transmission_interface/SimpleTransmission</type>
    <joint name="joint6">
      <hardwareInterface>hardware_interface/PositionJointInterface</hardwareInterface>
    </joint>
    <actuator name="motor6">
      <hardwareInterface>hardware_interface/PositionJointInterface</hardwareInterface>
      <mechanicalReduction>100</mechanicalReduction>
    </actuator>
  </transmission>
  <transmission name="tran7">
    <type>transmission_interface/SimpleTransmission</type>
    <joint name="joint7">
      <hardwareInterface>hardware_interface/PositionJointInterface</hardwareInterface>
    </joint>
    <actuator name="motor7">
      <hardwareInterface>hardware_interface/PositionJointInterface</hardwareInterface>
      <mechanicalReduction>100</mechanicalReduction>
    </actuator>
  </transmission>
  <gazebo reference="link_base">
    <selfCollide>true</selfCollide>
  </gazebo>
  <gazebo reference="link1">
    <selfCollide>true</selfCollide>
  </gazebo>
  <gazebo reference="link2">
    <selfCollide>true</selfCollide>
  </gazebo>
  <gazebo reference="link3">
    <selfCollide>true</selfCollide>
  </gazebo>
  <gazebo reference="link4">
    <selfCollide>true</selfCollide>
  </gazebo>
  <gazebo reference="link5">
    <selfCollide>true</selfCollide>
  </gazebo>
  <gazebo reference="link6">
    <selfCollide>true</selfCollide>
  </gazebo>
  <gazebo reference="link7">
    <selfCollide>true</selfCollide>
  </gazebo>
  <!-- gazebo plugin -->
  <!-- <xacro:gazebo_ros_control_plugin namespace="${ns}"/> -->
  <joint name="gripper_fix" type="fixed">
    <parent link="link_eef"/>
    <child link="xarm_gripper_base_link"/>
    <origin rpy="0 0 0" xyz="0 0 0"/>
  </joint>
  <link name="xarm_gripper_base_link">
    <inertial>
      <origin rpy="0 0 0" xyz="-0.00065489 -0.0018497 0.048028"/>
      <mass value="0.54156"/>
      <inertia ixx="0.00047106" ixy="3.9292E-07" ixz="2.6537E-06" iyy="0.00033072" iyz="-1.0975E-05" izz="0.00025642"/>
    </inertial>
    <visual>
      <origin rpy="0 0 0" xyz="0 0 0"/>
      <geometry>
        <mesh filename="package://xarm_gripper/meshes/base_link.STL"/>
      </geometry>
      <!-- <material
        name="">
        <color
          rgba="0.89804 0.91765 0.92941 1" />
      </material> -->
      <material name="White">
        <color rgba="1.0 1.0 1.0 1.0"/>
      </material>
    </visual>
    <collision>
      <origin rpy="0 0 0" xyz="0 0 0"/>
      <geometry>
        <mesh filename="package://xarm_gripper/meshes/base_link_collision.STL"/>
      </geometry>
    </collision>
  </link>
  <link name="left_outer_knuckle">
    <inertial>
      <origin rpy="0 0 0" xyz="2.9948E-14 0.021559 0.015181"/>
      <mass value="0.033618"/>
      <inertia ixx="1.9111E-05" ixy="-1.8803E-17" ixz="-1.1002E-17" iyy="6.6256E-06" iyz="-7.3008E-06" izz="1.3185E-05"/>
    </inertial>
    <visual>
      <origin rpy="0 0 0" xyz="0 0 0"/>
      <geometry>
        <mesh filename="package://xarm_gripper/meshes/left_outer_knuckle.STL"/>
      </geometry>
      <material name="Silver">
        <color rgba="0.753 0.753 0.753 1.0"/>
      </material>
    </visual>
    <collision>
      <origin rpy="0 0 0" xyz="0 0 0"/>
      <geometry>
        <mesh filename="package://xarm_gripper/meshes/left_outer_knuckle.STL"/>
      </geometry>
    </collision>
  </link>
  <joint name="drive_joint" type="revolute">
    <origin rpy="0 0 0" xyz="0 0.035 0.059098"/>
    <parent link="xarm_gripper_base_link"/>
    <child link="left_outer_knuckle"/>
    <axis xyz="1 0 0"/>
    <limit effort="50" lower="0" upper="0.85" velocity="2"/>
  </joint>
  <link name="left_finger">
    <inertial>
      <origin rpy="0 0 0" xyz="-2.4536E-14 -0.016413 0.029258"/>
      <mass value="0.048304"/>
      <inertia ixx="1.7493E-05" ixy="-4.2156E-19" ixz="6.9164E-18" iyy="1.7225E-05" iyz="4.6433E-06" izz="5.1466E-06"/>
    </inertial>
    <visual>
      <origin rpy="0 0 0" xyz="0 0 0"/>
      <geometry>
        <mesh filename="package://xarm_gripper/meshes/left_finger.STL"/>
      </geometry>
      <material name="Silver">
        <color rgba="0.753 0.753 0.753 1.0"/>
      </material>
    </visual>
    <collision>
      <origin rpy="0 0 0" xyz="0 0 0"/>
      <geometry>
        <mesh filename="package://xarm_gripper/meshes/left_finger.STL"/>
      </geometry>
    </collision>
  </link>
  <joint name="left_finger_joint" type="revolute">
    <origin rpy="0 0 0" xyz="0 0.035465 0.042039"/>
    <parent link="left_outer_knuckle"/>
    <child link="left_finger"/>
    <axis xyz="-1 0 0"/>
    <limit effort="50" lower="0" upper="0.85" velocity="2"/>
    <mimic joint="drive_joint" multiplier="1" offset="0"/>
  </joint>
  <link name="left_inner_knuckle">
    <inertial>
      <origin rpy="0 0 0" xyz="1.86600784687907E-06 0.0220467847633621 0.0261334672830885"/>
      <mass value="0.0230125781256706"/>
      <inertia ixx="6.09490024271906E-06" ixy="6.06651326160071E-11" ixz="7.19102670500635E-11" iyy="6.01955084375188E-06" iyz="-2.75316812991721E-06" izz="5.07862004479903E-06"/>
    </inertial>
    <visual>
      <origin rpy="0 0 0" xyz="0 0 0"/>
      <geometry>
        <mesh filename="package://xarm_gripper/meshes/left_inner_knuckle.STL"/>
      </geometry>
      <material name="Silver">
        <color rgba="0.753 0.753 0.753 1.0"/>
      </material>
    </visual>
    <collision>
      <origin rpy="0 0 0" xyz="0 0 0"/>
      <geometry>
        <mesh filename="package://xarm_gripper/meshes/left_inner_knuckle.STL"/>
      </geometry>
    </collision>
  </link>
  <joint name="left_inner_knuckle_joint" type="revolute">
    <origin rpy="0 0 0" xyz="0 0.02 0.074098"/>
    <parent link="xarm_gripper_base_link"/>
    <child link="left_inner_knuckle"/>
    <axis xyz="1 0 0"/>
    <limit effort="50" lower="0" upper="0.85" velocity="2"/>
    <mimic joint="drive_joint" multiplier="1" offset="0"/>
  </joint>
  <link name="right_outer_knuckle">
    <inertial>
      <origin rpy="0 0 0" xyz="-3.1669E-14 -0.021559 0.015181"/>
      <mass value="0.033618"/>
      <inertia ixx="1.9111E-05" ixy="-1.8789E-17" ixz="1.0986E-17" iyy="6.6256E-06" iyz="7.3008E-06" izz="1.3185E-05"/>
    </inertial>
    <visual>
      <origin rpy="0 0 0" xyz="0 0 0"/>
      <geometry>
        <mesh filename="package://xarm_gripper/meshes/right_outer_knuckle.STL"/>
      </geometry>
      <material name="Silver">
        <color rgba="0.753 0.753 0.753 1.0"/>
      </material>
    </visual>
    <collision>
      <origin rpy="0 0 0" xyz="0 0 0"/>
      <geometry>
        <mesh filename="package://xarm_gripper/meshes/right_outer_knuckle.STL"/>
      </geometry>
    </collision>
  </link>
  <joint name="right_outer_knuckle_joint" type="revolute">
    <origin rpy="0 0 0" xyz="0 -0.035 0.059098"/>
    <parent link="xarm_gripper_base_link"/>
    <child link="right_outer_knuckle"/>
    <axis xyz="-1 0 0"/>
    <limit effort="50" lower="0" upper="0.85" velocity="2"/>
    <mimic joint="drive_joint" multiplier="1" offset="0"/>
  </joint>
  <link name="right_finger">
    <inertial>
      <origin rpy="0 0 0" xyz="2.5618E-14 0.016413 0.029258"/>
      <mass value="0.048304"/>
      <inertia ixx="1.7493E-05" ixy="-5.0014E-19" ixz="-7.5079E-18" iyy="1.7225E-05" iyz="-4.6435E-06" izz="5.1466E-06"/>
    </inertial>
    <visual>
      <origin rpy="0 0 0" xyz="0 0 0"/>
      <geometry>
        <mesh filename="package://xarm_gripper/meshes/right_finger.STL"/>
      </geometry>
      <material name="Silver">
        <color rgba="0.753 0.753 0.753 1.0"/>
      </material>
    </visual>
    <collision>
      <origin rpy="0 0 0" xyz="0 0 0"/>
      <geometry>
        <mesh filename="package://xarm_gripper/meshes/right_finger.STL"/>
      </geometry>
    </collision>
  </link>
  <joint name="right_finger_joint" type="revolute">
    <origin rpy="0 0 0" xyz="0 -0.035465 0.042039"/>
    <parent link="right_outer_knuckle"/>
    <child link="right_finger"/>
    <axis xyz="1 0 0"/>
    <limit effort="50" lower="0" upper="0.85" velocity="2"/>
    <mimic joint="drive_joint" multiplier="1" offset="0"/>
  </joint>
  <link name="right_inner_knuckle">
    <inertial>
      <origin rpy="0 0 0" xyz="1.866E-06 -0.022047 0.026133"/>
      <mass value="0.023013"/>
      <inertia ixx="6.0949E-06" ixy="-6.0665E-11" ixz="7.191E-11" iyy="6.0197E-06" iyz="2.7531E-06" izz="5.0784E-06"/>
    </inertial>
    <visual>
      <origin rpy="0 0 0" xyz="0 0 0"/>
      <geometry>
        <mesh filename="package://xarm_gripper/meshes/right_inner_knuckle.STL"/>
      </geometry>
      <material name="Silver">
        <color rgba="0.753 0.753 0.753 1.0"/>
      </material>
    </visual>
    <collision>
      <origin rpy="0 0 0" xyz="0 0 0"/>
      <geometry>
        <mesh filename="package://xarm_gripper/meshes/right_inner_knuckle.STL"/>
      </geometry>
    </collision>
  </link>
  <joint name="right_inner_knuckle_joint" type="revolute">
    <origin rpy="0 0 0" xyz="0 -0.02 0.074098"/>
    <parent link="xarm_gripper_base_link"/>
    <child link="right_inner_knuckle"/>
    <axis xyz="-1 0 0"/>
    <limit effort="50" lower="0" upper="0.85" velocity="2"/>
    <mimic joint="drive_joint" multiplier="1" offset="0"/>
  </joint>
  <link name="link_tcp"/>
  <joint name="joint_tcp" type="fixed">
    <origin rpy="0 0 0" xyz="0 0 0.172"/>
    <parent link="xarm_gripper_base_link"/>
    <child link="link_tcp"/>
  </joint>
  <transmission name="drive_joint_trans">
    <type>transmission_interface/SimpleTransmission</type>
    <joint name="drive_joint">
      <hardwareInterface>hardware_interface/PositionJointInterface</hardwareInterface>
    </joint>
    <actuator name="drive_joint_motor">
      <hardwareInterface>hardware_interface/PositionJointInterface</hardwareInterface>
      <mechanicalReduction>1</mechanicalReduction>
    </actuator>
  </transmission>
  <gazebo reference="xarm_gripper_base_link">
    <selfCollide>false</selfCollide>
  </gazebo>
  <gazebo reference="left_outer_knuckle">
    <selfCollide>false</selfCollide>
  </gazebo>
  <gazebo reference="left_finger">
    <selfCollide>false</selfCollide>
  </gazebo>
  <gazebo reference="left_inner_knuckle">
    <selfCollide>false</selfCollide>
  </gazebo>
  <gazebo reference="right_outer_knuckle">
    <selfCollide>false</selfCollide>
  </gazebo>
  <gazebo reference="right_finger">
    <selfCollide>false</selfCollide>
  </gazebo>
  <gazebo reference="right_inner_knuckle">
    <selfCollide>false</selfCollide>
  </gazebo>
  <gazebo>
    <plugin filename="libgazebo_grasp_fix.so" name="gazebo_grasp_fix">
      <arm>
        <arm_name>xarm_gripper</arm_name>
        <palm_link>link7</palm_link>
        <gripper_link>left_inner_knuckle</gripper_link>
        <gripper_link>right_inner_knuckle</gripper_link>
        <!-- <gripper_link>${prefix}left_outer_knuckle</gripper_link>
          <gripper_link>${prefix}right_outer_knuckle</gripper_link> -->
        <gripper_link>left_finger</gripper_link>
        <gripper_link>right_finger</gripper_link>
      </arm>
      <forces_angle_tolerance>100</forces_angle_tolerance>
      <update_rate>10</update_rate>
      <grip_count_threshold>2</grip_count_threshold>
      <max_grip_count>3</max_grip_count>
      <release_tolerance>0.0198</release_tolerance>
      <disable_collisions_on_attach>false</disable_collisions_on_attach>
      <contact_topic>__default_topic__</contact_topic>
    </plugin>
  </gazebo>
  <gazebo>
    <!-- old version -->
    <plugin filename="libroboticsgroup_gazebo_mimic_joint_plugin.so" name="left_finger_jointmimic_joint_plugin">
      <!-- new version -->
      <!-- <plugin name="${name_prefix}mimic_joint_plugin" filename="libroboticsgroup_upatras_gazebo_mimic_joint_plugin.so"> -->
      <joint>drive_joint</joint>
      <mimicJoint>left_finger_joint</mimicJoint>
      <multiplier>1.0</multiplier>
      <offset>0</offset>
      <sensitiveness>0.0</sensitiveness>
      <!-- if absolute difference between setpoint and process value is below this threshold, do nothing; 0.0 = disable [rad] -->
      <maxEffort>10.0</maxEffort>
    </plugin>
  </gazebo>
  <gazebo>
    <!-- old version -->
    <plugin filename="libroboticsgroup_gazebo_mimic_joint_plugin.so" name="left_inner_knuckle_jointmimic_joint_plugin">
      <!-- new version -->
      <!-- <plugin name="${name_prefix}mimic_joint_plugin" filename="libroboticsgroup_upatras_gazebo_mimic_joint_plugin.so"> -->
      <joint>drive_joint</joint>
      <mimicJoint>left_inner_knuckle_joint</mimicJoint>
      <multiplier>1.0</multiplier>
      <offset>0</offset>
      <sensitiveness>0.0</sensitiveness>
      <!-- if absolute difference between setpoint and process value is below this threshold, do nothing; 0.0 = disable [rad] -->
      <maxEffort>10.0</maxEffort>
    </plugin>
  </gazebo>
  <gazebo>
    <!-- old version -->
    <plugin filename="libroboticsgroup_gazebo_mimic_joint_plugin.so" name="right_outer_knuckle_jointmimic_joint_plugin">
      <!-- new version -->
      <!-- <plugin name="${name_prefix}mimic_joint_plugin" filename="libroboticsgroup_upatras_gazebo_mimic_joint_plugin.so"> -->
      <joint>drive_joint</joint>
      <mimicJoint>right_outer_knuckle_joint</mimicJoint>
      <multiplier>1.0</multiplier>
      <offset>0</offset>
      <sensitiveness>0.0</sensitiveness>
      <!-- if absolute difference between setpoint and process value is below this threshold, do nothing; 0.0 = disable [rad] -->
      <maxEffort>10.0</maxEffort>
    </plugin>
  </gazebo>
  <gazebo>
    <!-- old version -->
    <plugin filename="libroboticsgroup_gazebo_mimic_joint_plugin.so" name="right_finger_jointmimic_joint_plugin">
      <!-- new version -->
      <!-- <plugin name="${name_prefix}mimic_joint_plugin" filename="libroboticsgroup_upatras_gazebo_mimic_joint_plugin.so"> -->
      <joint>drive_joint</joint>
      <mimicJoint>right_finger_joint</mimicJoint>
      <multiplier>1.0</multiplier>
      <offset>0</offset>
      <sensitiveness>0.0</sensitiveness>
      <!-- if absolute difference between setpoint and process value is below this threshold, do nothing; 0.0 = disable [rad] -->
      <maxEffort>10.0</maxEffort>
    </plugin>
  </gazebo>
  <gazebo>
    <!-- old version -->
    <plugin filename="libroboticsgroup_gazebo_mimic_joint_plugin.so" name="right_inner_knuckle_jointmimic_joint_plugin">
      <!-- new version -->
      <!-- <plugin name="${name_prefix}mimic_joint_plugin" filename="libroboticsgroup_upatras_gazebo_mimic_joint_plugin.so"> -->
      <joint>drive_joint</joint>
      <mimicJoint>right_inner_knuckle_joint</mimicJoint>
      <multiplier>1.0</multiplier>
      <offset>0</offset>
      <sensitiveness>0.0</sensitiveness>
      <!-- if absolute difference between setpoint and process value is below this threshold, do nothing; 0.0 = disable [rad] -->
      <maxEffort>10.0</maxEffort>
    </plugin>
  </gazebo>
</robot>

