<?xml version="1.0" encoding="utf-8"?>
<!-- =================================================================================== -->
<!-- |    This document was autogenerated by xacro from xarm7_with_gripper.xacro       | -->
<!-- |    EDITING THIS FILE BY HAND IS NOT RECOMMENDED                                 | -->
<!-- =================================================================================== -->
<robot name="xarm7">
  <!--
  Author: Jimy Zhang <jimy.zhang@ufactory.cc> <jimy92@163.com>
  Contributers:
-->
  <link name="world"/>
  <joint name="world_joint" type="fixed">
    <parent link="world"/>
    <child link="link_base"/>
    <origin rpy="0 0 0" xyz="0 0 0"/>
  </joint>
  <material name="Black">
    <color rgba="0.0 0.0 0.0 1.0"/>
  </material>
  <material name="Red">
    <color rgba="0.8 0.0 0.0 1.0"/>
  </material>
  <material name="White">
    <color rgba="0.0 1.0 1.0 1.0"/>
  </material>
  <material name="Silver">
    <color rgba="0.753 0.753 0.753 1.0"/>
  </material>
  <link name="link_base">
    <inertial>
      <origin rpy="0 0 0" xyz="-0.021131 -0.0016302 0.056488"/>
      <mass value="2.612"/>
      <inertia ixx="0.0030595" ixy="0.00012259" ixz="-0.00062705" iyy="0.0037783" iyz="0.00027023" izz="0.0020125"/>
    </inertial>
    <visual>
      <origin rpy="0 0 0" xyz="0 0 0"/>
      <geometry>
        <mesh filename="xarm_description/meshes/xarm7/visual/link_base_textured.glb"/>
      </geometry>
      <material name="White"/>
    </visual>
    <collision>
      <origin rpy="0 0 0" xyz="0 0 0"/>
      <geometry>
        <mesh filename="xarm_description/meshes/xarm7/visual/link_base_textured.glb"/>
      </geometry>
    </collision>
  </link>
  <link name="link1">
    <inertial>
      <origin rpy="0 0 0" xyz="0.00013 0.0301 -0.012"/>
      <mass value="2.459"/>
      <inertia ixx="0.005795" ixy="-1.078E-05" ixz="-2.63E-05" iyy="0.004969" iyz="0.000911" izz="0.003428"/>
    </inertial>
    <visual>
      <origin rpy="0 0 0" xyz="0 0 0"/>
      <geometry>
        <mesh filename="xarm_description/meshes/xarm7/visual/link1_textured.glb"/>
      </geometry>
      <material name="White"/>
    </visual>
    <collision>
      <origin rpy="0 0 0" xyz="0 0 0"/>
      <geometry>
        <mesh filename="xarm_description/meshes/xarm7/visual/link1_textured.glb"/>
      </geometry>
    </collision>
  </link>
  <joint name="joint1" type="revolute">
    <origin rpy="0 0 0" xyz="0 0 0.267"/>
    <parent link="link_base"/>
    <child link="link1"/>
    <axis xyz="0 0 1"/>
    <limit effort="50" lower="-6.28318530718" upper="6.28318530718" velocity="3.14"/>
    <dynamics damping="10" friction="1"/>
  </joint>
  <link name="link2">
    <inertial>
      <origin rpy="0 0 0" xyz="0.0002 -0.12964 0.01692"/>
      <mass value="1.916"/>
      <inertia ixx="0.0097184" ixy="1.0E-06" ixz="-4.83E-06" iyy="0.0038705" iyz="0.0032" izz="0.007672"/>
    </inertial>
    <visual>
      <origin rpy="0 0 0" xyz="0 0 0"/>
      <geometry>
        <mesh filename="xarm_description/meshes/xarm7/visual/link2_textured.glb"/>
      </geometry>
      <material name="White"/>
    </visual>
    <collision>
      <origin rpy="0 0 0" xyz="0 0 0"/>
      <geometry>
        <mesh filename="xarm_description/meshes/xarm7/visual/link2_textured.glb"/>
      </geometry>
    </collision>
  </link>
  <joint name="joint2" type="revolute">
    <origin rpy="-1.5708 0 0" xyz="0 0 0"/>
    <parent link="link1"/>
    <child link="link2"/>
    <axis xyz="0 0 1"/>
    <limit effort="50" lower="-2.059" upper="2.0944" velocity="3.14"/>
    <dynamics damping="10" friction="1"/>
  </joint>
  <link name="link3">
    <inertial>
      <origin rpy="0 0 0" xyz="0.04676 -0.02526 -0.00746"/>
      <mass value="1.6854"/>
      <inertia ixx="0.0031588" ixy="-3.1443E-04" ixz="5.8658E-04" iyy="0.002682" iyz="-3.469E-04" izz="0.0027105"/>
    </inertial>
    <visual>
      <origin rpy="0 0 0" xyz="0 0 0"/>
      <geometry>
        <mesh filename="xarm_description/meshes/xarm7/visual/link3_textured.glb"/>
      </geometry>
      <material name="White"/>
    </visual>
    <collision>
      <origin rpy="0 0 0" xyz="0 0 0"/>
      <geometry>
        <mesh filename="xarm_description/meshes/xarm7/visual/link3_textured.glb"/>
      </geometry>
    </collision>
  </link>
  <joint name="joint3" type="revolute">
    <origin rpy="1.5708 0 0" xyz="0 -0.293 0"/>
    <parent link="link2"/>
    <child link="link3"/>
    <axis xyz="0 0 1"/>
    <limit effort="30" lower="-6.28318530718" upper="6.28318530718" velocity="3.14"/>
    <dynamics damping="5" friction="1"/>
  </joint>
  <link name="link4">
    <inertial>
      <origin rpy="0 0 0" xyz="0.07066 -0.11664 0.0117"/>
      <mass value="1.774"/>
      <inertia ixx="0.005967" ixy="-0.001382" ixz="-0.00088544" iyy="0.00363897" iyz="0.0017806" izz="0.005509226"/>
    </inertial>
    <visual>
      <origin rpy="0 0 0" xyz="0 0 0"/>
      <geometry>
        <mesh filename="xarm_description/meshes/xarm7/visual/link4_textured.glb"/>
      </geometry>
      <material name="White"/>
    </visual>
    <collision>
      <origin rpy="0 0 0" xyz="0 0 0"/>
      <geometry>
        <mesh filename="xarm_description/meshes/xarm7/visual/link4_textured.glb"/>
      </geometry>
    </collision>
  </link>
  <joint name="joint4" type="revolute">
    <origin rpy="1.5708 0 0" xyz="0.0525 0 0"/>
    <parent link="link3"/>
    <child link="link4"/>
    <axis xyz="0 0 1"/>
    <limit effort="30" lower="-0.19198" upper="3.927" velocity="3.14"/>
    <dynamics damping="5" friction="1"/>
  </joint>
  <link name="link5">
    <inertial>
      <origin rpy="0 0 0" xyz="-0.00031 0.01558 -0.0253"/>
      <mass value="1.357"/>
      <inertia ixx="0.005396" ixy="-1.53E-05" ixz="-6.7E-07" iyy="0.005" iyz="0.00020544" izz="0.00138734"/>
    </inertial>
    <visual>
      <origin rpy="0 0 0" xyz="0 0 0"/>
      <geometry>
        <mesh filename="xarm_description/meshes/xarm7/visual/link5_textured.glb"/>
      </geometry>
      <material name="White"/>
    </visual>
    <collision>
      <origin rpy="0 0 0" xyz="0 0 0"/>
      <geometry>
        <mesh filename="xarm_description/meshes/xarm7/visual/link5_textured.glb"/>
      </geometry>
    </collision>
  </link>
  <joint name="joint5" type="revolute">
    <origin rpy="1.5708 0 0" xyz="0.0775 -0.3425 0"/>
    <parent link="link4"/>
    <child link="link5"/>
    <axis xyz="0 0 1"/>
    <limit effort="30" lower="-6.28318530718" upper="6.28318530718" velocity="3.14"/>
    <dynamics damping="5" friction="1"/>
  </joint>
  <link name="link6">
    <inertial>
      <origin rpy="0 0 0" xyz="0.065 0.03336 0.02131"/>
      <mass value="1.362"/>
      <inertia ixx="0.0015057" ixy="0.000496735" ixz="-2.9968E-04" iyy="0.0019297" iyz="-1.5E-04" izz="0.0024"/>
    </inertial>
    <visual>
      <origin rpy="0 0 0" xyz="0 0 0"/>
      <geometry>
        <mesh filename="xarm_description/meshes/xarm7/visual/link6_textured.glb"/>
      </geometry>
      <material name="White"/>
    </visual>
    <collision>
      <origin rpy="0 0 0" xyz="0 0 0"/>
      <geometry>
        <mesh filename="xarm_description/meshes/xarm7/visual/link6_textured.glb"/>
      </geometry>
    </collision>
  </link>
  <joint name="joint6" type="revolute">
    <origin rpy="1.5708 0 0" xyz="0 0 0"/>
    <parent link="link5"/>
    <child link="link6"/>
    <axis xyz="0 0 1"/>
    <limit effort="20" lower="-1.69297" upper="3.14159265359" velocity="3.14"/>
    <dynamics damping="2" friction="1"/>
  </joint>
  <link name="link7">
    <inertial>
      <origin rpy="0 0 0" xyz="0 -0.00677 -0.01098"/>
      <mass value="0.17"/>
      <inertia ixx="9.3E-05" ixy="0.0" ixz="0.0" iyy="5.87E-05" iyz="3.6E-06" izz="1.32E-04"/>
    </inertial>
    <visual>
      <origin rpy="0 0 0" xyz="0 0 0"/>
      <geometry>
        <mesh filename="xarm_description/meshes/xarm7/visual/link7_silver.glb"/>
      </geometry>
      <material name="Silver"/>
    </visual>
    <collision>
      <origin rpy="0 0 0" xyz="0 0 0"/>
      <geometry>
        <mesh filename="xarm_description/meshes/collision/end_tool.STL"/>
      </geometry>
    </collision>
  </link>
  <joint name="joint7" type="revolute">
    <origin rpy="-1.5708 0 0" xyz="0.076 0.097 0"/>
    <parent link="link6"/>
    <child link="link7"/>
    <axis xyz="0 0 1"/>
    <limit effort="20" lower="-6.28318530718" upper="6.28318530718" velocity="3.14"/>
    <dynamics damping="2" friction="1"/>
  </joint>
  <link name="link_eef"/>
  <joint name="joint_eef" type="fixed">
    <origin rpy="0 0 0" xyz="0 0 0"/>
    <parent link="link7"/>
    <child link="link_eef"/>
  </joint>

  <joint name="gripper_fix" type="fixed">
    <parent link="link_eef"/>
    <child link="xarm_gripper_base_link"/>
    <origin rpy="0 0 0" xyz="0 0 0"/>
  </joint>
  <link name="xarm_gripper_base_link">
    <inertial>
      <origin rpy="0 0 0" xyz="-0.00065489 -0.0018497 0.048028"/>
      <mass value="0.54156"/>
      <inertia ixx="0.00047106" ixy="3.9292E-07" ixz="2.6537E-06" iyy="0.00033072" iyz="-1.0975E-05" izz="0.00025642"/>
    </inertial>
    <visual>
      <origin rpy="0 0 0" xyz="0 0 0"/>
      <geometry>
        <mesh filename="xarm_gripper/meshes/base_link.STL"/>
      </geometry>
      <material name="White">
        <color rgba="1.0 1.0 1.0 1.0"/>
      </material>
    </visual>
    <collision>
      <origin rpy="0 0 0" xyz="0 0 0"/>
      <geometry>
        <mesh filename="xarm_gripper/meshes/base_link_collision.STL"/>
      </geometry>
    </collision>
  </link>
  <link name="left_finger">
    <inertial>
      <origin rpy="0 0 0" xyz="-2.4536E-14 -0.016413 0.029258"/>
      <mass value="0.048304"/>
      <inertia ixx="1.7493E-05" ixy="-4.2156E-19" ixz="6.9164E-18" iyy="1.7225E-05" iyz="4.6433E-06" izz="5.1466E-06"/>
    </inertial>
    <visual>
      <origin rpy="0 0 0" xyz="0 0 0"/>
      <geometry>
        <mesh filename="xarm_gripper/meshes/left_finger_black.glb"/>
      </geometry>
      <material name="Silver">
        <color rgba="0.753 0.753 0.753 1.0"/>
      </material>
    </visual>
    <collision>
      <origin rpy="0 0 0" xyz="0 0 0"/>
      <geometry>
        <mesh filename="xarm_gripper/meshes/left_finger_black.glb"/>
      </geometry>
    </collision>
  </link>
  <joint name="left_finger_joint" type="prismatic">
    <origin rpy="0 0 0" xyz="0 0.07 0.101"/>
    <parent link="xarm_gripper_base_link"/>
    <child link="left_finger"/>
    <axis xyz="0 -0.9631963 0.26879897"/>
    <limit effort="50" lower="0" upper="0.0446430" velocity="0.5"/>
  </joint>
  <link name="right_finger">
    <inertial>
      <origin rpy="0 0 0" xyz="2.5618E-14 0.016413 0.029258"/>
      <mass value="0.048304"/>
      <inertia ixx="1.7493E-05" ixy="-5.0014E-19" ixz="-7.5079E-18" iyy="1.7225E-05" iyz="-4.6435E-06"
               izz="5.1466E-06"/>
    </inertial>
    <visual>
      <origin rpy="0 0 0" xyz="0 0 0"/>
      <geometry>
        <mesh filename="xarm_gripper/meshes/right_finger_black.glb"/>
      </geometry>
      <material name="Silver">
        <color rgba="0.753 0.753 0.753 1.0"/>
      </material>
    </visual>
    <collision>
      <origin rpy="0 0 0" xyz="0 0 0"/>
      <geometry>
        <mesh filename="xarm_gripper/meshes/right_finger_black.glb"/>
      </geometry>
    </collision>
  </link>
  <joint name="right_finger_joint" type="prismatic">
    <origin rpy="0 0 0" xyz="0 -0.07 0.101"/>
    <parent link="xarm_gripper_base_link"/>
    <child link="right_finger"/>
    <axis xyz="0. 0.9631963 0.26879897"/>
    <limit effort="50" lower="0" upper="0.0446430" velocity="0.5"/>
  </joint>
  <link name="link_tcp"/>
  <joint name="joint_tcp" type="fixed">
    <origin rpy="0 0 0" xyz="0 0 0.172"/>
    <parent link="xarm_gripper_base_link"/>
    <child link="link_tcp"/>
  </joint>
</robot>